[20:06:12.614] Running build in Washington, D.C., USA (East) â€“ iad1
[20:06:12.724] Cloning github.com/rlim99/SmartGrocery (Branch: main, Commit: efd13a5)
[20:06:13.069] Cloning completed: 345.000ms
[20:06:13.306] Restored build cache from previous deployment (G14ZbtfB74uFgJYibqCWcczK6j8R)
[20:06:13.385] Running "vercel build"
[20:06:13.775] Vercel CLI 41.1.3
[20:06:13.886] WARN! Due to `builds` existing in your configuration file, the Build and Development Settings defined in your Project Settings will not apply. Learn More: https://vercel.link/unused-build-settings
[20:06:13.909] Installing required dependencies...
[20:06:20.961] Build Completed in /vercel/output [7s]
[20:06:21.179] Deploying outputs...
[20:06:38.801] 
[20:06:39.093] Deployment completed
[20:06:40.178] Uploading build cache [29.00 B]...
[20:06:40.265] Build cache uploaded: 87.154ms
=============================================================
Traceback (most recent call last):
File "/var/task/vc__handler__python.py", line 14, in <module>
__vc_spec.loader.exec_module(__vc_module)
File "<frozen importlib._bootstrap_external>", line 995, in exec_module
File "<frozen importlib._bootstrap>", line 488, in _call_with_frames_removed
File "/var/task/app.py", line 10, in <module>
from barcode_functions import capture_image, recognize_barcode, recognize_item, count_quantity_from_image
File "/var/task/barcode_functions.py", line 6, in <module>
from image_processing import process_image
File "/var/task/image_processing.py", line 6, in <module>
import tensorflow as tf
ModuleNotFoundError: No module named 'tensorflow'
Python process exited with exit status: 1. The logs above can help with debugging the issue.
Traceback (most recent call last):
File "/var/task/vc__handler__python.py", line 14, in <module>
__vc_spec.loader.exec_module(__vc_module)
File "<frozen importlib._bootstrap_external>", line 995, in exec_module
File "<frozen importlib._bootstrap>", line 488, in _call_with_frames_removed
File "/var/task/app.py", line 10, in <module>
from barcode_functions import capture_image, recognize_barcode, recognize_item, count_quantity_from_image
File "/var/task/barcode_functions.py", line 6, in <module>
from image_processing import process_image
File "/var/task/image_processing.py", line 6, in <module>
import tensorflow as tf
ModuleNotFoundError: No module named 'tensorflow'
Python process exited with exit status: 1. The logs above can help with debugging the issue.
===========================================================================
Traceback (most recent call last):
File "/var/task/vc__handler__python.py", line 14, in <module>
__vc_spec.loader.exec_module(__vc_module)
File "<frozen importlib._bootstrap_external>", line 995, in exec_module
File "<frozen importlib._bootstrap>", line 488, in _call_with_frames_removed
File "/var/task/app.py", line 10, in <module>
from barcode_functions import capture_image, recognize_barcode, recognize_item, count_quantity_from_image
File "/var/task/barcode_functions.py", line 6, in <module>
from image_processing import process_image
File "/var/task/image_processing.py", line 6, in <module>
import tensorflow as tf
ModuleNotFoundError: No module named 'tensorflow'
Python process exited with exit status: 1. The logs above can help with debugging the issue.
Traceback (most recent call last):
File "/var/task/vc__handler__python.py", line 14, in <module>
__vc_spec.loader.exec_module(__vc_module)
File "<frozen importlib._bootstrap_external>", line 995, in exec_module
File "<frozen importlib._bootstrap>", line 488, in _call_with_frames_removed
File "/var/task/app.py", line 10, in <module>
from barcode_functions import capture_image, recognize_barcode, recognize_item, count_quantity_from_image
File "/var/task/barcode_functions.py", line 6, in <module>
from image_processing import process_image
File "/var/task/image_processing.py", line 6, in <module>
import tensorflow as tf
ModuleNotFoundError: No module named 'tensorflow'
Python process exited with exit status: 1. The logs above can help with debugging the issue.
======================================================================
Traceback (most recent call last):
File "/var/task/vc__handler__python.py", line 14, in <module>
__vc_spec.loader.exec_module(__vc_module)
File "<frozen importlib._bootstrap_external>", line 995, in exec_module
File "<frozen importlib._bootstrap>", line 488, in _call_with_frames_removed
File "/var/task/app.py", line 10, in <module>
from barcode_functions import capture_image, recognize_barcode, recognize_item, count_quantity_from_image
File "/var/task/barcode_functions.py", line 6, in <module>
from image_processing import process_image
File "/var/task/image_processing.py", line 6, in <module>
import tensorflow as tf
ModuleNotFoundError: No module named 'tensorflow'
Python process exited with exit status: 1. The logs above can help with debugging the issue.
Traceback (most recent call last):
File "/var/task/vc__handler__python.py", line 14, in <module>
__vc_spec.loader.exec_module(__vc_module)
File "<frozen importlib._bootstrap_external>", line 995, in exec_module
File "<frozen importlib._bootstrap>", line 488, in _call_with_frames_removed
File "/var/task/app.py", line 10, in <module>
from barcode_functions import capture_image, recognize_barcode, recognize_item, count_quantity_from_image
File "/var/task/barcode_functions.py", line 6, in <module>
from image_processing import process_image
File "/var/task/image_processing.py", line 6, in <module>
import tensorflow as tf
ModuleNotFoundError: No module named 'tensorflow'
Python process exited with exit status: 1. The logs above can help with debugging the issue.
[[[[[[[[[[[[[[[[[[[[[[[[[[[[[[[[[[[[[[[[[[[[[[[[[[[[[[[[[[[[[[[[[[[[[[[[[[
Traceback (most recent call last):
File "/var/task/vc__handler__python.py", line 14, in <module>
__vc_spec.loader.exec_module(__vc_module)
File "<frozen importlib._bootstrap_external>", line 995, in exec_module
File "<frozen importlib._bootstrap>", line 488, in _call_with_frames_removed
File "/var/task/app.py", line 10, in <module>
from barcode_functions import capture_image, recognize_barcode, recognize_item, count_quantity_from_image
File "/var/task/barcode_functions.py", line 6, in <module>
from image_processing import process_image
File "/var/task/image_processing.py", line 6, in <module>
import tensorflow as tf
ModuleNotFoundError: No module named 'tensorflow'
Python process exited with exit status: 1. The logs above can help with debugging the issue.
Traceback (most recent call last):
File "/var/task/vc__handler__python.py", line 14, in <module>
__vc_spec.loader.exec_module(__vc_module)
File "<frozen importlib._bootstrap_external>", line 995, in exec_module
File "<frozen importlib._bootstrap>", line 488, in _call_with_frames_removed
File "/var/task/app.py", line 10, in <module>
from barcode_functions import capture_image, recognize_barcode, recognize_item, count_quantity_from_image
File "/var/task/barcode_functions.py", line 6, in <module>
from image_processing import process_image
File "/var/task/image_processing.py", line 6, in <module>
import tensorflow as tf
ModuleNotFoundError: No module named 'tensorflow'
Python process exited with exit status: 1. The logs above can help with debugging the issue.
=========================================================================
Traceback (most recent call last):
File "/var/task/vc__handler__python.py", line 14, in <module>
__vc_spec.loader.exec_module(__vc_module)
File "<frozen importlib._bootstrap_external>", line 995, in exec_module
File "<frozen importlib._bootstrap>", line 488, in _call_with_frames_removed
File "/var/task/app.py", line 10, in <module>
from barcode_functions import capture_image, recognize_barcode, recognize_item, count_quantity_from_image
File "/var/task/barcode_functions.py", line 6, in <module>
from image_processing import process_image
File "/var/task/image_processing.py", line 6, in <module>
import tensorflow as tf
ModuleNotFoundError: No module named 'tensorflow'
Python process exited with exit status: 1. The logs above can help with debugging the issue.
Traceback (most recent call last):
File "/var/task/vc__handler__python.py", line 14, in <module>
__vc_spec.loader.exec_module(__vc_module)
File "<frozen importlib._bootstrap_external>", line 995, in exec_module
File "<frozen importlib._bootstrap>", line 488, in _call_with_frames_removed
File "/var/task/app.py", line 10, in <module>
from barcode_functions import capture_image, recognize_barcode, recognize_item, count_quantity_from_image
File "/var/task/barcode_functions.py", line 6, in <module>
from image_processing import process_image
File "/var/task/image_processing.py", line 6, in <module>
import tensorflow as tf
ModuleNotFoundError: No module named 'tensorflow'
Python process exited with exit status: 1. The logs above can help with debugging the issue.
=======================================================
3.12/site-packages/pip/_internal/cli/base_command.py", line 105, in _run_wrapper
status = _inner_run()
^^^^^^^^^^^^
File "/var/lang/lib/python3.12/site-packages/pip/_internal/cli/base_command.py", line 96, in _inner_run
return self.run(options, args)
^^^^^^^^^^^^^^^^^^^^^^^
File "/var/lang/lib/python3.12/site-packages/pip/_internal/cli/req_command.py", line 67, in wrapper
return func(self, options, args)
^^^^^^^^^^^^^^^^^^^^^^^^^
File "/var/lang/lib/python3.12/site-packages/pip/_internal/commands/install.py", line 334, in run
build_tracker = self.enter_context(get_build_tracker())
^^^^^^^^^^^^^^^^^^^^^^^^^^^^^^^^^^^^^^^
File "/var/lang/lib/python3.12/site-packages/pip/_internal/cli/command_context.py", line 27, in enter_context
return self._main_context.enter_context(context_provider)
^^^^^^^^^^^^^^^^^^^^^^^^^^^^^^^^^^^^^^^^^^^^^^^^^^
File "/var/lang/lib/python3.12/contextlib.py", line 526, in enter_context
result = _enter(cm)
^^^^^^^^^^
File "/var/lang/lib/python3.12/contextlib.py", line 137, in __enter__
return next(self.gen)
^^^^^^^^^^^^^^
File "/var/lang/lib/python3.12/site-packages/pip/_internal/operations/build/build_tracker.py", line 45, in get_build_tracker
root = ctx.enter_context(TempDirectory(kind="build-tracker")).path
^^^^^^^^^^^^^^^^^^^^^^^^^^^^^^^^^^^
File "/var/lang/lib/python3.12/site-packages/pip/_internal/utils/temp_dir.py", line 137, in __init__
path = self._create(kind)
^^^^^^^^^^^^^^^^^^
File "/var/lang/lib/python3.12/site-packages/pip/_internal/utils/temp_dir.py", line 177, in _create
path = os.path.realpath(tempfile.mkdtemp(prefix=f"pip-{kind}-"))
^^^^^^^^^^^^^^^^^^^^^^^^^^^^^^^^^^^^^^^
File "/var/lang/lib/python3.12/tempfile.py", line 373, in mkdtemp
prefix, suffix, dir, output_type = _sanitize_params(prefix, suffix, dir)
^^^^^^^^^^^^^^^^^^^^^^^^^^^^^^^^^^^^^
File "/var/lang/lib/python3.12/tempfile.py", line 126, in _sanitize_params
dir = gettempdir()
^^^^^^^^^^^^
File "/var/lang/lib/python3.12/tempfile.py", line 315, in gettempdir
return _os.fsdecode(_gettempdir())
^^^^^^^^^^^^^
File "/var/lang/lib/python3.12/tempfile.py", line 308, in _gettempdir
tempdir = _get_default_tempdir()
^^^^^^^^^^^^^^^^^^^^^^
File "/var/lang/lib/python3.12/tempfile.py", line 223, in _get_default_tempdir
raise FileNotFoundError(_errno.ENOENT,
FileNotFoundError: [Errno 2] No usable temporary directory found in ['/tmp', '/var/tmp', '/usr/tmp', '/var/task']
Traceback (most recent call last):
File "/var/task/image_processing.py", line 12, in <module>
import tensorflow as tf
ModuleNotFoundError: No module named 'tensorflow'
During handling of the above exception, another exception occurred:
Traceback (most recent call last):
File "/var/task/vc__handler__python.py", line 14, in <module>
__vc_spec.loader.exec_module(__vc_module)
File "<frozen importlib._bootstrap_external>", line 995, in exec_module
File "<frozen importlib._bootstrap>", line 488, in _call_with_frames_removed
File "/var/task/app.py", line 10, in <module>
from barcode_functions import capture_image, recognize_barcode, recognize_item, count_quantity_from_image
File "/var/task/barcode_functions.py", line 6, in <module>
from image_processing import process_image
File "/var/task/image_processing.py", line 15, in <module>
subprocess.check_call([sys.executable, '-m', 'pip', 'install', 'tensorflow-cpu==2.18.0'])
File "/var/lang/lib/python3.12/subprocess.py", line 413, in check_call
raise CalledProcessError(retcode, cmd)
subprocess.CalledProcessError: Command '['/var/lang/bin/python', '-m', 'pip', 'install', 'tensorflow-cpu==2.18.0']' returned non-zero exit status 2.
Python process exited with exit status: 1. The logs above can help with debugging the issue.